Workbook

Sheet chl
A1: Cruise #: | B1: Date | C1: LTER Station | D1: Cast # | E1: Niskin # | F1: Time In | G1: Time Out | H1: Replicate | I1: Vol Filt | J1: Filter Size | K1: Vol Extracted | L1: Sample | M1: 90% Acetone | N1: Dilution During Reading | O1: Chl_Cal_Filename | P1: tau_Calibration | Q1: Fd_Calibration | R1: Rb | S1: Ra | T1: blank | U1: Rb-blank | V1: Ra-blank | W1: Chl (ug/l) | X1: Phaeo (ug/l) | Y1: Cal_Date | Z1: Lab notebook and Page number | AA1: Date_analyzed | AB1: cruise_project_type | AC1: Personnel Filter | AD1: Personnel Read | AE1: Fluorometer | AF1: quality_flag | AG1: QC_d | AH1: Comments | AI1: Comments2
A2: AR22 | B2: 20170902 | D2: 1 | E2: 1 | H2: a | I2: 535 | J2: 0 | K2: 10 | L2: 1 | M2: 0 | N2: 1 | O2: =Cal_110119!$P$3 -> Cal_110119 | P2: =Cal_110119!$Q$3 -> 1.8682 | Q2: =Cal_110119!$R$3 -> 0.5122 | R2: 163.3 | S2: 104.2 | T2: 0.78916667 | U2: =(R2-T2)*(L2+M2)/L2 -> 162.51083 | V2: =(S2-T2)*(L2+M2)/L2 -> 103.41083 | W2: =(Q2*P2/(P2-1)*(U2-V2)*(K2)/I2)/N2 -> 1.2175221 | X2: =(Q2*P2/(P2-1)*(P2*V2-U2)*(K2)/I2)/N2 -> 0.63206673 | Y2: =Cal_110119!$O$3 -> 20181101 | Z2: 9-58 | AB2: 3 | AD2: Emily | AE2: Turner Designs Aquafluor Handheld Serial Number 800446 | AF2: 1 | AG2: 0
A3: AR22 | B3: 20170902 | D3: 1 | E3: 1 | H3: b | I3: 535 | J3: 0 | K3: 5 | L3: 1 | M3: 0 | N3: 1 | O3: Cal_012618_12mm | P3: =Cal_012618_12mm!$Q$3 -> 1.9020156 | Q3: =Cal_012618_12mm!$R$3 -> 0.48423689 | R3: 355.8 | S3: 222 | T3: =AVERAGE(0.598,0.717,0.487,0.777,0.635,0.748) -> 0.66033333 | U3: =(R3-T3)*(L3+M3)/L3 -> 355.13967 | V3: =(S3-T3)*(L3+M3)/L3 -> 221.33967 | W3: =(Q3*P3/(P3-1)*(U3-V3)*(K3)/I3)/N3 -> 1.2768217 | X3: =(Q3*P3/(P3-1)*(P3*V3-U3)*(K3)/I3)/N3 -> 0.62840834 | Y3: 20180126 | Z3: 8-69 | AB3: 3 | AD3: Emily | AE3: Turner Designs Aquafluor Handheld Serial Number 800446 | AF3: 1 | AG3: 0
A4: AR22 | B4: 20170902 | D4: 1 | E4: 2 | H4: a | I4: 535 | J4: 0 | K4: 5 | L4: 1 | M4: 0 | N4: 1 | O4: Cal_012618_12mm | P4: =Cal_012618_12mm!$Q$3 -> 1.9020156 | Q4: =Cal_012618_12mm!$R$3 -> 0.48423689 | R4: 345.8 | S4: 212.1 | T4: 0.66033 | U4: =(R4-T4)*(L4+M4)/L4 -> 345.13967 | V4: =(S4-T4)*(L4+M4)/L4 -> 211.43967 | W4: =(Q4*P4/(P4-1)*(U4-V4)*(K4)/I4)/N4 -> 1.2758674 | X4: =(Q4*P4/(P4-1)*(P4*V4-U4)*(K4)/I4)/N4 -> 0.54414621 | Y4: 20180126 | Z4: 8-69 | AB4: 3 | AD4: Emily | AE4: Turner Designs Aquafluor Handheld Serial Number 800446 | AF4: 4 | AG4: 1 | AH4: "leak at beginning"
A5: AR22 | B5: 20170902 | D5: 1 | E5: 2 | H5: b | I5: 535 | J5: 0 | K5: 10 | L5: 1 | M5: 0 | N5: 1 | O5: =Cal_110119!$P$3 -> Cal_110119 | P5: =Cal_110119!$Q$3 -> 1.8682 | Q5: =Cal_110119!$R$3 -> 0.5122 | R5: 198.3 | S5: 125.3 | T5: 0.78916667 | U5: =(R5-T5)*(L5+M5)/L5 -> 197.51083 | V5: =(S5-T5)*(L5+M5)/L5 -> 124.51083 | W5: =(Q5*P5/(P5-1)*(U5-V5)*(K5)/I5)/N5 -> 1.5038767 | X5: =(Q5*P5/(P5-1)*(P5*V5-U5)*(K5)/I5)/N5 -> 0.72310319 | Y5: =Cal_110119!$O$3 -> 20181101 | Z5: 9-58 | AB5: 3 | AD5: Emily | AE5: Turner Designs Aquafluor Handheld Serial Number 800446 | AF5: 1 | AG5: 1
A6: AR22 | B6: 20170902 | D6: 1 | E6: 3 | H6: a | I6: 535 | J6: 0 | K6: 5 | L6: 1 | M6: 0 | N6: 1 | O6: Cal_012618_12mm | P6: =Cal_012618_12mm!$Q$3 -> 1.9020156 | Q6: =Cal_012618_12mm!$R$3 -> 0.48423689 | R6: 414 | S6: 248.5 | T6: 0.66033 | U6: =(R6-T6)*(L6+M6)/L6 -> 413.33967 | V6: =(S6-T6)*(L6+M6)/L6 -> 247.83967 | W6: =(Q6*P6/(P6-1)*(U6-V6)*(K6)/I6)/N6 -> 1.5793273 | X6: =(Q6*P6/(P6-1)*(P6*V6-U6)*(K6)/I6)/N6 -> 0.55400739 | Y6: 20180126 | Z6: 8-69 | AB6: 3 | AD6: Emily | AE6: Turner Designs Aquafluor Handheld Serial Number 800446 | AF6: 1 | AG6: 0
A7: AR22 | B7: 20170902 | D7: 1 | E7: 3 | H7: b | I7: 535 | J7: 0 | K7: 5 | L7: 1 | M7: 0 | N7: 1 | O7: Cal_012618_12mm | P7: =Cal_012618_12mm!$Q$3 -> 1.9020156 | Q7: =Cal_012618_12mm!$R$3 -> 0.48423689 | R7: 397.5 | S7: 243.2 | T7: 0.66033 | U7: =(R7-T7)*(L7+M7)/L7 -> 396.83967 | V7: =(S7-T7)*(L7+M7)/L7 -> 242.53967 | W7: =(Q7*P7/(P7-1)*(U7-V7)*(K7)/I7)/N7 -> 1.4724483 | X7: =(Q7*P7/(P7-1)*(P7*V7-U7)*(K7)/I7)/N7 -> 0.61526541 | Y7: 20180126 | Z7: 8-69 | AB7: 3 | AD7: Emily | AE7: Turner Designs Aquafluor Handheld Serial Number 800446 | AF7: 1 | AG7: 0
A8: AR22 | B8: 20170902 | D8: 1 | E8: 4 | H8: a | I8: 535 | J8: 0 | K8: 5 | L8: 1 | M8: 0 | N8: 1 | O8: Cal_012618_12mm | P8: =Cal_012618_12mm!$Q$3 -> 1.9020156 | Q8: =Cal_012618_12mm!$R$3 -> 0.48423689 | R8: 304.3 | S8: 184.6 | T8: 0.66033 | U8: =(R8-T8)*(L8+M8)/L8 -> 303.63967 | V8: =(S8-T8)*(L8+M8)/L8 -> 183.93967 | W8: =(Q8*P8/(P8-1)*(U8-V8)*(K8)/I8)/N8 -> 1.1422687 | X8: =(Q8*P8/(P8-1)*(P8*V8-U8)*(K8)/I8)/N8 -> 0.44103258 | Y8: 20180126 | Z8: 8-69 | AB8: 3 | AD8: Emily | AE8: Turner Designs Aquafluor Handheld Serial Number 800446 | AF8: 1 | AG8: 0
A9: AR22 | B9: 20170902 | D9: 1 | E9: 4 | H9: b | I9: 535 | J9: 0 | K9: 5 | L9: 1 | M9: 0 | N9: 1 | O9: Cal_012618_12mm | P9: =Cal_012618_12mm!$Q$3 -> 1.9020156 | Q9: =Cal_012618_12mm!$R$3 -> 0.48423689 | R9: 297.6 | S9: 180.2 | T9: 0.66033 | U9: =(R9-T9)*(L9+M9)/L9 -> 296.93967 | V9: =(S9-T9)*(L9+M9)/L9 -> 179.53967 | W9: =(Q9*P9/(P9-1)*(U9-V9)*(K9)/I9)/N9 -> 1.1203204 | X9: =(Q9*P9/(P9-1)*(P9*V9-U9)*(K9)/I9)/N9 -> 0.42510696 | Y9: 20180126 | Z9: 8-69 | AB9: 3 | AD9: Emily | AE9: Turner Designs Aquafluor Handheld Serial Number 800446 | AF9: 1 | AG9: 0
A10: AR22 | B10: 20170902 | D10: 1 | E10: 4 | H10: a | I10: 535 | J10: 10 | K10: 5 | L10: 1 | M10: 0 | N10: 1 | O10: Cal_012618_12mm | P10: =Cal_012618_12mm!$Q$3 -> 1.9020156 | Q10: =Cal_012618_12mm!$R$3 -> 0.48423689 | R10: 249.8 | S10: 149.3 | T10: =AVERAGE(0.939,0.988,0.789,0.968,0.875,0.717) -> 0.87933333 | U10: =(R10-T10)*(L10+M10)/L10 -> 248.92067 | V10: =(S10-T10)*(L10+M10)/L10 -> 148.42067 | W10: =(Q10*P10/(P10-1)*(U10-V10)*(K10)/I10)/N10 -> 0.95904767 | X10: =(Q10*P10/(P10-1)*(P10*V10-U10)*(K10)/I10)/N10 -> 0.31851597 | Y10: 20180126 | Z10: 8-76 | AB10: 3 | AD10: Emily | AE10: Turner Designs Aquafluor Handheld Serial Number 800446 | AF10: 3 | AG10: 1 | AH10: poor replication, was this pre-filtered correctly?
A11: AR22 | B11: 20170902 | D11: 1 | E11: 4 | H11: b | I11: 535 | J11: 10 | K11: 5 | L11: 1 | M11: 0 | N11: 1 | O11: Cal_012618_12mm | P11: =Cal_012618_12mm!$Q$3 -> 1.9020156 | Q11: =Cal_012618_12mm!$R$3 -> 0.48423689 | R11: 182.6 | S11: 114.1 | T11: 0.66033 | U11: =(R11-T11)*(L11+M11)/L11 -> 181.93967 | V11: =(S11-T11)*(L11+M11)/L11 -> 113.43967 | W11: =(Q11*P11/(P11-1)*(U11-V11)*(K11)/I11)/N11 -> 0.65367925 | X11: =(Q11*P11/(P11-1)*(P11*V11-U11)*(K11)/I11)/N11 -> 0.32277773 | Y11: 20180126 | Z11: 8-69 | AB11: 3 | AD11: Emily | AE11: Turner Designs Aquafluor Handheld Serial Number 800446 | AF11: 3 | AG11: 1 | AH11: poor replication
A12: AR22 | B12: 20170902 | D12: 2 | E12: 1 | H12: a | I12: 535 | J12: 0 | K12: 5 | L12: 1 | M12: 0 | N12: 1 | O12: Cal_012618_12mm | P12: =Cal_012618_12mm!$Q$3 -> 1.9020156 | Q12: =Cal_012618_12mm!$R$3 -> 0.48423689 | R12: 267.4 | S12: 163.7 | T12: 0.66033 | U12: =(R12-T12)*(L12+M12)/L12 -> 266.73967 | V12: =(S12-T12)*(L12+M12)/L12 -> 163.03967 | W12: =(Q12*P12/(P12-1)*(U12-V12)*(K12)/I12)/N12 -> 0.98958451 | X12: =(Q12*P12/(P12-1)*(P12*V12-U12)*(K12)/I12)/N12 -> 0.41381542 | Y12: 20180126 | Z12: 8-69 | AB12: 3 | AD12: Emily | AE12: Turner Designs Aquafluor Handheld Serial Number 800446 | AF12: 1 | AG12: 0
A13: AR22 | B13: 20170902 | D13: 2 | E13: 1 | H13: b | I13: 535 | J13: 0 | K13: 5 | L13: 1 | M13: 0 | N13: 1 | O13: Cal_012618_12mm | P13: =Cal_012618_12mm!$Q$3 -> 1.9020156 | Q13: =Cal_012618_12mm!$R$3 -> 0.48423689 | R13: 263.3 | S13: 160.7 | T13: 0.66033 | U13: =(R13-T13)*(L13+M13)/L13 -> 262.63967 | V13: =(S13-T13)*(L13+M13)/L13 -> 160.03967 | W13: =(Q13*P13/(P13-1)*(U13-V13)*(K13)/I13)/N13 -> 0.97908747 | X13: =(Q13*P13/(P13-1)*(P13*V13-U13)*(K13)/I13)/N13 -> 0.3984893 | Y13: 20180126 | Z13: 8-69 | AB13: 3 | AD13: Emily | AE13: Turner Designs Aquafluor Handheld Serial Number 800446 | AF13: 1 | AG13: 0
A14: AR22 | B14: 20170902 | D14: 2 | E14: 2 | H14: a | I14: 535 | J14: 0 | K14: 5 | L14: 1 | M14: 0 | N14: 1 | O14: Cal_012618_12mm | P14: =Cal_012618_12mm!$Q$3 -> 1.9020156 | Q14: =Cal_012618_12mm!$R$3 -> 0.48423689 | R14: 146.6 | S14: 95.89 | T14: 0.493 | U14: =(R14-T14)*(L14+M14)/L14 -> 146.107 | V14: =(S14-T14)*(L14+M14)/L14 -> 95.397 | W14: =(Q14*P14/(P14-1)*(U14-V14)*(K14)/I14)/N14 -> 0.4839135 | X14: =(Q14*P14/(P14-1)*(P14*V14-U14)*(K14)/I14)/N14 -> 0.33723722 | Y14: 20180126 | Z14: 8-65 | AB14: 3 | AD14: Emily | AE14: Turner Designs Aquafluor Handheld Serial Number 800446 | AF14: 1 | AG14: 0 | AH14: a?
A15: AR22 | B15: 20170902 | D15: 2 | E15: 2 | H15: b | I15: 535 | J15: 0 | K15: 5 | L15: 1 | M15: 0 | N15: 1 | O15: Cal_012618_12mm | P15: =Cal_012618_12mm!$Q$3 -> 1.9020156 | Q15: =Cal_012618_12mm!$R$3 -> 0.48423689 | R15: 166.3 | S15: 104.5 | T15: 0.66033 | U15: =(R15-T15)*(L15+M15)/L15 -> 165.63967 | V15: =(S15-T15)*(L15+M15)/L15 -> 103.83967 | W15: =(Q15*P15/(P15-1)*(U15-V15)*(K15)/I15)/N15 -> 0.58974274 | X15: =(Q15*P15/(P15-1)*(P15*V15-U15)*(K15)/I15)/N15 -> 0.30408012 | Y15: 20180126 | Z15: 8-69 | AB15: 3 | AD15: Emily | AE15: Turner Designs Aquafluor Handheld Serial Number 800446 | AF15: 1 | AG15: 0
A16: AR22 | B16: 20170902 | D16: 2 | E16: 3 | H16: a | I16: 535 | J16: 0 | K16: 5 | L16: 1 | M16: 0 | N16: 1 | O16: Cal_012618_12mm | P16: =Cal_012618_12mm!$Q$3 -> 1.9020156 | Q16: =Cal_012618_12mm!$R$3 -> 0.48423689 | R16: 371.7 | S16: 234.1 | T16: 0.66033 | U16: =(R16-T16)*(L16+M16)/L16 -> 371.03967 | V16: =(S16-T16)*(L16+M16)/L16 -> 233.43967 | W16: =(Q16*P16/(P16-1)*(U16-V16)*(K16)/I16)/N16 -> 1.3130842 | X16: =(Q16*P16/(P16-1)*(P16*V16-U16)*(K16)/I16)/N16 -> 0.69629929 | Y16: 20180126 | Z16: 8-69 | AB16: 3 | AD16: Emily | AE16: Turner Designs Aquafluor Handheld Serial Number 800446 | AF16: 1 | AG16: 0
A17: AR22 | B17: 20170902 | D17: 2 | E17: 3 | H17: b | I17: 535 | J17: 0 | K17: 5 | L17: 1 | M17: 0 | N17: 1 | O17: Cal_012618_12mm | P17: =Cal_012618_12mm!$Q$3 -> 1.9020156 | Q17: =Cal_012618_12mm!$R$3 -> 0.48423689 | R17: 384.7 | S17: 239.3 | T17: 0.66033 | U17: =(R17-T17)*(L17+M17)/L17 -> 384.03967 | V17: =(S17-T17)*(L17+M17)/L17 -> 238.63967 | W17: =(Q17*P17/(P17-1)*(U17-V17)*(K17)/I17)/N17 -> 1.3875177 | X17: =(Q17*P17/(P17-1)*(P17*V17-U17)*(K17)/I17)/N17 -> 0.66662589 | Y17: 20180126 | Z17: 8-69 | AB17: 3 | AD17: Emily | AE17: Turner Designs Aquafluor Handheld Serial Number 800446 | AF17: 1 | AG17: 0
A18: AR22 | B18: 20170902 | D18: 2 | E18: 4 | H18: a | I18: 535 | J18: 0 | K18: 5 | L18: 1 | M18: 0 | N18: 1 | O18: Cal_012618_12mm | P18: =Cal_012618_12mm!$Q$3 -> 1.9020156 | Q18: =Cal_012618_12mm!$R$3 -> 0.48423689 | R18: 335 | S18: 208.4 | T18: 0.66033 | U18: =(R18-T18)*(L18+M18)/L18 -> 334.33967 | V18: =(S18-T18)*(L18+M18)/L18 -> 207.73967 | W18: =(Q18*P18/(P18-1)*(U18-V18)*(K18)/I18)/N18 -> 1.2081138 | X18: =(Q18*P18/(P18-1)*(P18*V18-U18)*(K18)/I18)/N18 -> 0.58005126 | Y18: 20180126 | Z18: 8-69 | AB18: 3 | AD18: Emily | AE18: Turner Designs Aquafluor Handheld Serial Number 800446 | AF18: 1 | AG18: 0
A19: AR22 | B19: 20170902 | D19: 2 | E19: 4 | H19: b | I19: 535 | J19: 0 | K19: 5 | L19: 1 | M19: 0 | N19: 1 | O19: Cal_012618_12mm | P19: =Cal_012618_12mm!$Q$3 -> 1.9020156 | Q19: =Cal_012618_12mm!$R$3 -> 0.48423689 | R19: 330.9 | S19: 208.5 | T19: 0.66033 | U19: =(R19-T19)*(L19+M19)/L19 -> 330.23967 | V19: =(S19-T19)*(L19+M19)/L19 -> 207.83967 | W19: =(Q19*P19/(P19-1)*(U19-V19)*(K19)/I19)/N19 -> 1.1680342 | X19: =(Q19*P19/(P19-1)*(P19*V19-U19)*(K19)/I19)/N19 -> 0.62099164 | Y19: 20180126 | Z19: 8-69 | AB19: 3 | AD19: Emily | AE19: Turner Designs Aquafluor Handheld Serial Number 800446 | AF19: 1 | AG19: 0
A20: AR22 | B20: 20170902 | D20: 2 | E20: 5 | H20: a | I20: 535 | J20: 0 | K20: 5 | L20: 1 | M20: 0 | N20: 1 | O20: Cal_012618_12mm | P20: =Cal_012618_12mm!$Q$3 -> 1.9020156 | Q20: =Cal_012618_12mm!$R$3 -> 0.48423689 | R20: 217.4 | S20: 134 | T20: 0.66033 | U20: =(R20-T20)*(L20+M20)/L20 -> 216.73967 | V20: =(S20-T20)*(L20+M20)/L20 -> 133.33967 | W20: =(Q20*P20/(P20-1)*(U20-V20)*(K20)/I20)/N20 -> 0.79586642 | X20: =(Q20*P20/(P20-1)*(P20*V20-U20)*(K20)/I20)/N20 -> 0.3518842 | Y20: 20180126 | Z20: 8-69 | AB20: 3 | AD20: Emily | AE20: Turner Designs Aquafluor Handheld Serial Number 800446 | AF20: 1 | AG20: 0
A21: AR22 | B21: 20170902 | D21: 2 | E21: 5 | H21: b | I21: 535 | J21: 0 | K21: 5 | L21: 1 | M21: 0 | N21: 1 | O21: =Cal_110119!$P$3 -> Cal_110119 | P21: =Cal_110119!$Q$3 -> 1.8682 | Q21: =Cal_110119!$R$3 -> 0.5122 | R21: 187.4 | S21: 118.4 | T21: 0.78916667 | U21: =(R21-T21)*(L21+M21)/L21 -> 186.61083 | V21: =(S21-T21)*(L21+M21)/L21 -> 117.61083 | W21: =(Q21*P21/(P21-1)*(U21-V21)*(K21)/I21)/N21 -> 0.71073626 | X21: =(Q21*P21/(P21-1)*(P21*V21-U21)*(K21)/I21)/N21 -> 0.34104757 | Y21: =Cal_110119!$O$3 -> 20181101 | Z21: 9-58 | AB21: 3 | AD21: Emily | AE21: Turner Designs Aquafluor Handheld Serial Number 800446 | AF21: 1 | AG21: 0
A22: AR22 | B22: 20170902 | D22: 2 | E22: 6 | H22: a | I22: 540 | J22: 0 | K22: 5 | L22: 1 | M22: 0 | N22: 1 | O22: Cal_012618_12mm | P22: =Cal_012618_12mm!$Q$3 -> 1.9020156 | Q22: =Cal_012618_12mm!$R$3 -> 0.48423689 | R22: 192.6 | S22: 116.7 | T22: 0.78916667 | U22: =(R22-T22)*(L22+M22)/L22 -> 191.81083 | V22: =(S22-T22)*(L22+M22)/L22 -> 115.91083 | W22: =(Q22*P22/(P22-1)*(U22-V22)*(K22)/I22)/N22 -> 0.71758926 | X22: =(Q22*P22/(P22-1)*(P22*V22-U22)*(K22)/I22)/N22 -> 0.27090059 | Y22: 20180126 | Z22: 8-76 | AB22: 3 | AD22: Emily | AE22: Turner Designs Aquafluor Handheld Serial Number 800446 | AF22: 3 | AG22: 1 | AH22: looks like C2N6a accidentally switched with C2N6 10b. Switch values
A23: AR22 | B23: 20170902 | D23: 2 | E23: 6 | H23: b | I23: 540 | J23: 0 | K23: 5 | L23: 1 | M23: 0 | N23: 1 | O23: Cal_012618_12mm | P23: =Cal_012618_12mm!$Q$3 -> 1.9020156 | Q23: =Cal_012618_12mm!$R$3 -> 0.48423689 | R23: 185.6 | S23: 112.8 | T23: 0.87933 | U23: =(R23-T23)*(L23+M23)/L23 -> 184.72067 | V23: =(S23-T23)*(L23+M23)/L23 -> 111.92067 | W23: =(Q23*P23/(P23-1)*(U23-V23)*(K23)/I23)/N23 -> 0.68828061 | X23: =(Q23*P23/(P23-1)*(P23*V23-U23)*(K23)/I23)/N23 -> 0.26618105 | Y23: 20180126 | Z23: 8-76 | AB23: 3 | AD23: Emily | AE23: Turner Designs Aquafluor Handheld Serial Number 800446 | AF23: 1 | AG23: 1
A24: AR22 | B24: 20170902 | D24: 2 | E24: 6 | H24: a | I24: 540 | J24: 10 | K24: 5 | L24: 1 | M24: 0 | N24: 1 | O24: Cal_012618_12mm | P24: =Cal_012618_12mm!$Q$3 -> 1.9020156 | Q24: =Cal_012618_12mm!$R$3 -> 0.48423689 | R24: 165 | S24: 100.7 | T24: 0.493 | U24: =(R24-T24)*(L24+M24)/L24 -> 164.507 | V24: =(S24-T24)*(L24+M24)/L24 -> 100.207 | W24: =(Q24*P24/(P24-1)*(U24-V24)*(K24)/I24)/N24 -> 0.60791817 | X24: =(Q24*P24/(P24-1)*(P24*V24-U24)*(K24)/I24)/N24 -> 0.24664908 | Y24: 20180126 | Z24: 8-65 | AB24: 3 | AD24: Emily | AE24: Turner Designs Aquafluor Handheld Serial Number 800446 | AF24: 1 | AG24: 1
A25: AR22 | B25: 20170902 | D25: 2 | E25: 6 | H25: b | I25: 540 | J25: 10 | K25: 5 | L25: 1 | M25: 0 | N25: 1 | O25: =Cal_110119!$P$3 -> Cal_110119 | P25: =Cal_110119!$Q$3 -> 1.8682 | Q25: =Cal_110119!$R$3 -> 0.5122 | R25: 158.4 | S25: 100.4 | T25: 0.87933 | U25: =(R25-T25)*(L25+M25)/L25 -> 157.52067 | V25: =(S25-T25)*(L25+M25)/L25 -> 99.52067 | W25: =(Q25*P25/(P25-1)*(U25-V25)*(K25)/I25)/N25 -> 0.59189872 | X25: =(Q25*P25/(P25-1)*(P25*V25-U25)*(K25)/I25)/N25 -> 0.28986551 | Y25: =Cal_110119!$O$3 -> 20181101 | Z25: 9-58 | AB25: 3 | AD25: Emily | AE25: Turner Designs Aquafluor Handheld Serial Number 800446 | AF25: 3 | AG25: 1 | AH25: looks like C2N6a accidentally switched with C2N6 10a. Switch values
A26: AR22 | B26: 20170902 | D26: 3 | E26: 1 | H26: a | I26: 535 | J26: 0 | K26: 5 | L26: 1 | M26: 0 | N26: 1 | O26: Cal_012618_12mm | P26: =Cal_012618_12mm!$Q$3 -> 1.9020156 | Q26: =Cal_012618_12mm!$R$3 -> 0.48423689 | R26: 103.9 | S26: 71.56 | T26: 0.87933 | U26: =(R26-T26)*(L26+M26)/L26 -> 103.02067 | V26: =(S26-T26)*(L26+M26)/L26 -> 70.68067 | W26: =(Q26*P26/(P26-1)*(U26-V26)*(K26)/I26)/N26 -> 0.30861295 | X26: =(Q26*P26/(P26-1)*(P26*V26-U26)*(K26)/I26)/N26 -> 0.29978651 | Y26: 20180126 | Z26: 8-76 | AB26: 3 | AD26: Emily | AE26: Turner Designs Aquafluor Handheld Serial Number 800446 | AF26: 3 | AG26: 1 | AH26: tissue capsule was labeled 03-02a but does not match the 02b rep well, and the questionable repc does. This matched the 01b rep better and 01a was never found
A27: AR22 | B27: 20170902 | D27: 3 | E27: 1 | H27: b | I27: 535 | J27: 0 | K27: 5 | L27: 1 | M27: 0 | N27: 1 | O27: Cal_012618_12mm | P27: =Cal_012618_12mm!$Q$3 -> 1.9020156 | Q27: =Cal_012618_12mm!$R$3 -> 0.48423689 | R27: 108 | S27: 77.8 | T27: 0.66033 | U27: =(R27-T27)*(L27+M27)/L27 -> 107.33967 | V27: =(S27-T27)*(L27+M27)/L27 -> 77.13967 | W27: =(Q27*P27/(P27-1)*(U27-V27)*(K27)/I27)/N27 -> 0.28819144 | X27: =(Q27*P27/(P27-1)*(P27*V27-U27)*(K27)/I27)/N27 -> 0.37580529 | Y27: 20180126 | Z27: 8-69 | AB27: 3 | AD27: Emily | AE27: Turner Designs Aquafluor Handheld Serial Number 800446 | AF27: 1 | AG27: 0
A28: AR22 | B28: 20170902 | D28: 3 | E28: 2 | H28: a | I28: 535 | J28: 0 | K28: 5 | L28: 1 | M28: 0 | N28: 1 | O28: Cal_012618_12mm | P28: =Cal_012618_12mm!$Q$3 -> 1.9020156 | Q28: =Cal_012618_12mm!$R$3 -> 0.48423689 | R28: 124.7 | S28: 83.43 | T28: 0.66033 | U28: =(R28-T28)*(L28+M28)/L28 -> 124.03967 | V28: =(S28-T28)*(L28+M28)/L28 -> 82.76967 | W28: =(Q28*P28/(P28-1)*(U28-V28)*(K28)/I28)/N28 -> 0.39382982 | X28: =(Q28*P28/(P28-1)*(P28*V28-U28)*(K28)/I28)/N28 -> 0.31862837 | Y28: 20180126 | Z28: 8-69 | AB28: 3 | AD28: Emily | AE28: Turner Designs Aquafluor Handheld Serial Number 800446 | AF28: 3 | AG28: 0 | AH28: tissue capsule labeled 03-02c. Decide it was supposed to say a. Matched rep b well
A29: AR22 | B29: 20170902 | D29: 3 | E29: 2 | H29: b | I29: 535 | J29: 0 | K29: 5 | L29: 1 | M29: 0 | N29: 1 | O29: Cal_012618_12mm | P29: =Cal_012618_12mm!$Q$3 -> 1.9020156 | Q29: =Cal_012618_12mm!$R$3 -> 0.48423689 | R29: 123.4 | S29: 82.22 | T29: 0.87933 | U29: =(R29-T29)*(L29+M29)/L29 -> 122.52067 | V29: =(S29-T29)*(L29+M29)/L29 -> 81.34067 | W29: =(Q29*P29/(P29-1)*(U29-V29)*(K29)/I29)/N29 -> 0.39297097 | X29: =(Q29*P29/(P29-1)*(P29*V29-U29)*(K29)/I29)/N29 -> 0.30718679 | Y29: 20180126 | Z29: 8-76 | AB29: 3 | AD29: Emily | AE29: Turner Designs Aquafluor Handheld Serial Number 800446 | AF29: 1 | AG29: 0 | AH29: replaced replicate a with c? as provided in the lab notebook 8, pg 69
A30: AR22 | B30: 20170902 | D30: 3 | E30: 3 | H30: a | I30: 535 | J30: 0 | K30: 5 | L30: 1 | M30: 0 | N30: 1 | O30: Cal_012618_12mm | P30: =Cal_012618_12mm!$Q$3 -> 1.9020156 | Q30: =Cal_012618_12mm!$R$3 -> 0.48423689 | R30: 92.73 | S30: 61.74 | T30: 0.66033 | U30: =(R30-T30)*(L30+M30)/L30 -> 92.06967 | V30: =(S30-T30)*(L30+M30)/L30 -> 61.07967 | W30: =(Q30*P30/(P30-1)*(U30-V30)*(K30)/I30)/N30 -> 0.29573022 | X30: =(Q30*P30/(P30-1)*(P30*V30-U30)*(K30)/I30)/N30 -> 0.23002651 | Y30: 20180126 | Z30: 8-69 | AB30: 3 | AD30: Emily | AE30: Turner Designs Aquafluor Handheld Serial Number 800446 | AF30: 1 | AG30: 0
A31: AR22 | B31: 20170902 | D31: 3 | E31: 3 | H31: b | I31: 535 | J31: 0 | K31: 5 | L31: 1 | M31: 0 | N31: 1 | O31: Cal_012618_12mm | P31: =Cal_012618_12mm!$Q$3 -> 1.9020156 | Q31: =Cal_012618_12mm!$R$3 -> 0.48423689 | R31: 88.81 | S31: 60.01 | T31: 0.493 | U31: =(R31-T31)*(L31+M31)/L31 -> 88.317 | V31: =(S31-T31)*(L31+M31)/L31 -> 59.517 | W31: =(Q31*P31/(P31-1)*(U31-V31)*(K31)/I31)/N31 -> 0.27483157 | X31: =(Q31*P31/(P31-1)*(P31*V31-U31)*(K31)/I31)/N31 -> 0.23747414 | Y31: 20180126 | Z31: 8-65 | AB31: 3 | AD31: Emily | AE31: Turner Designs Aquafluor Handheld Serial Number 800446 | AF31: 1 | AG31: 0 | AH31: recorded as replicate b in lab notebook 8-69
A32: AR22 | B32: 20170902 | D32: 3 | E32: 4 | H32: a | I32: 535 | J32: 0 | K32: 5 | L32: 1 | M32: 0 | N32: 1 | O32: Cal_012618_12mm | P32: =Cal_012618_12mm!$Q$3 -> 1.9020156 | Q32: =Cal_012618_12mm!$R$3 -> 0.48423689 | R32: 208.7 | S32: 137.7 | T32: 0.66033 | U32: =(R32-T32)*(L32+M32)/L32 -> 208.03967 | V32: =(S32-T32)*(L32+M32)/L32 -> 137.03967 | W32: =(Q32*P32/(P32-1)*(U32-V32)*(K32)/I32)/N32 -> 0.67753616 | X32: =(Q32*P32/(P32-1)*(P32*V32-U32)*(K32)/I32)/N32 -> 0.50206303 | Y32: 20180126 | Z32: 8-69 | AB32: 3 | AD32: Emily | AE32: Turner Designs Aquafluor Handheld Serial Number 800446 | AF32: 1 | AG32: 0
A33: AR22 | B33: 20170902 | D33: 3 | E33: 4 | H33: b | I33: 535 | J33: 0 | K33: 5 | L33: 1 | M33: 0 | N33: 1 | O33: Cal_012618_12mm | P33: =Cal_012618_12mm!$Q$3 -> 1.9020156 | Q33: =Cal_012618_12mm!$R$3 -> 0.48423689 | R33: 214.8 | S33: 139.4 | T33: 0.87933 | U33: =(R33-T33)*(L33+M33)/L33 -> 213.92067 | V33: =(S33-T33)*(L33+M33)/L33 -> 138.52067 | W33: =(Q33*P33/(P33-1)*(U33-V33)*(K33)/I33)/N33 -> 0.71952432 | X33: =(Q33*P33/(P33-1)*(P33*V33-U33)*(K33)/I33)/N33 -> 0.47282291 | Y33: 20180126 | Z33: 8-76 | AB33: 3 | AD33: Emily | AE33: Turner Designs Aquafluor Handheld Serial Number 800446 | AF33: 1 | AG33: 0
A34: AR22 | B34: 20170902 | D34: 3 | E34: 5 | H34: a | I34: 535 | J34: 0 | K34: 5 | L34: 1 | M34: 0 | N34: 1 | O34: Cal_012618_12mm | P34: =Cal_012618_12mm!$Q$3 -> 1.9020156 | Q34: =Cal_012618_12mm!$R$3 -> 0.48423689 | R34: 466.1 | S34: 301 | T34: 0.493 | U34: =(R34-T34)*(L34+M34)/L34 -> 465.607 | V34: =(S34-T34)*(L34+M34)/L34 -> 300.507 | W34: =(Q34*P34/(P34-1)*(U34-V34)*(K34)/I34)/N34 -> 1.5755101 | X34: =(Q34*P34/(P34-1)*(P34*V34-U34)*(K34)/I34)/N34 -> 1.0111702 | Y34: 20180126 | Z34: 8-65 | AB34: 3 | AD34: Emily | AE34: Turner Designs Aquafluor Handheld Serial Number 800446 | AF34: 1 | AG34: 0
A35: AR22 | B35: 20170902 | D35: 3 | E35: 5 | H35: b | I35: 535 | J35: 0 | K35: 5 | L35: 1 | M35: 0 | N35: 1 | O35: Cal_012618_12mm | P35: =Cal_012618_12mm!$Q$3 -> 1.9020156 | Q35: =Cal_012618_12mm!$R$3 -> 0.48423689 | R35: 465.6 | S35: 296.9 | T35: 0.87933 | U35: =(R35-T35)*(L35+M35)/L35 -> 464.72067 | V35: =(S35-T35)*(L35+M35)/L35 -> 296.02067 | W35: =(Q35*P35/(P35-1)*(U35-V35)*(K35)/I35)/N35 -> 1.6098641 | X35: =(Q35*P35/(P35-1)*(P35*V35-U35)*(K35)/I35)/N35 -> 0.93819913 | Y35: 20180126 | Z35: 8-76 | AB35: 3 | AD35: Emily | AE35: Turner Designs Aquafluor Handheld Serial Number 800446 | AF35: 1 | AG35: 0
A36: AR22 | B36: 20170902 | D36: 3 | E36: 6 | H36: a | I36: 540 | J36: 0 | K36: 5 | L36: 1 | M36: 0 | N36: 1 | O36: Cal_012618_12mm | P36: =Cal_012618_12mm!$Q$3 -> 1.9020156 | Q36: =Cal_012618_12mm!$R$3 -> 0.48423689 | R36: 148.4 | S36: 96.64 | T36: 0.87933 | U36: =(R36-T36)*(L36+M36)/L36 -> 147.52067 | V36: =(S36-T36)*(L36+M36)/L36 -> 95.76067 | W36: =(Q36*P36/(P36-1)*(U36-V36)*(K36)/I36)/N36 -> 0.48935995 | X36: =(Q36*P36/(P36-1)*(P36*V36-U36)*(K36)/I36)/N36 -> 0.32728891 | Y36: 20180126 | Z36: 8-76 | AB36: 3 | AD36: Emily | AE36: Turner Designs Aquafluor Handheld Serial Number 800446 | AF36: 1 | AG36: 0
A37: AR22 | B37: 20170902 | D37: 3 | E37: 6 | H37: b | I37: 540 | J37: 0 | K37: 5 | L37: 1 | M37: 0 | N37: 1 | O37: Cal_012618_12mm | P37: =Cal_012618_12mm!$Q$3 -> 1.9020156 | Q37: =Cal_012618_12mm!$R$3 -> 0.48423689 | R37: 154.8 | S37: 99.94 | T37: 0.66033 | U37: =(R37-T37)*(L37+M37)/L37 -> 154.13967 | V37: =(S37-T37)*(L37+M37)/L37 -> 99.27967 | W37: =(Q37*P37/(P37-1)*(U37-V37)*(K37)/I37)/N37 -> 0.5186686 | X37: =(Q37*P37/(P37-1)*(P37*V37-U37)*(K37)/I37)/N37 -> 0.32799036 | Y37: 20180126 | Z37: 8-69 | AB37: 3 | AD37: Emily | AE37: Turner Designs Aquafluor Handheld Serial Number 800446 | AF37: 1 | AG37: 0
A38: AR22 | B38: 20170902 | D38: 3 | E38: 6 | H38: a | I38: 540 | J38: 10 | K38: 5 | L38: 1 | M38: 0 | N38: 1 | O38: Cal_012618_12mm | P38: =Cal_012618_12mm!$Q$3 -> 1.9020156 | Q38: =Cal_012618_12mm!$R$3 -> 0.48423689 | R38: 133.4 | S38: 85.49 | T38: 0.66033 | U38: =(R38-T38)*(L38+M38)/L38 -> 132.73967 | V38: =(S38-T38)*(L38+M38)/L38 -> 84.82967 | W38: =(Q38*P38/(P38-1)*(U38-V38)*(K38)/I38)/N38 -> 0.45296049 | X38: =(Q38*P38/(P38-1)*(P38*V38-U38)*(K38)/I38)/N38 -> 0.27046859 | Y38: 20180126 | Z38: 8-69 | AB38: 3 | AD38: Emily | AE38: Turner Designs Aquafluor Handheld Serial Number 800446 | AF38: 1 | AG38: 0 | AH38: There is no <10b
A39: AR22 | B39: 20170902 | D39: 4 | E39: 1 | H39: a | I39: 535 | J39: 0 | K39: 5 | L39: 1 | M39: 0 | N39: 1 | O39: Cal_012618_12mm | P39: =Cal_012618_12mm!$Q$3 -> 1.9020156 | Q39: =Cal_012618_12mm!$R$3 -> 0.48423689 | R39: 114.7 | S39: 76.89 | T39: 0.66033 | U39: =(R39-T39)*(L39+M39)/L39 -> 114.03967 | V39: =(S39-T39)*(L39+M39)/L39 -> 76.22967 | W39: =(Q39*P39/(P39-1)*(U39-V39)*(K39)/I39)/N39 -> 0.36081186 | X39: =(Q39*P39/(P39-1)*(P39*V39-U39)*(K39)/I39)/N39 -> 0.29535184 | Y39: 20180126 | Z39: 8-69 | AB39: 3 | AD39: Emily | AE39: Turner Designs Aquafluor Handheld Serial Number 800446 | AF39: 1 | AG39: 0
A40: AR22 | B40: 20170902 | D40: 4 | E40: 1 | H40: b | I40: 535 | J40: 0 | K40: 5 | L40: 1 | M40: 0 | N40: 1 | O40: Cal_012618_12mm | P40: =Cal_012618_12mm!$Q$3 -> 1.9020156 | Q40: =Cal_012618_12mm!$R$3 -> 0.48423689 | R40: 117 | S40: 80.2 | T40: 0.66033 | U40: =(R40-T40)*(L40+M40)/L40 -> 116.33967 | V40: =(S40-T40)*(L40+M40)/L40 -> 79.53967 | W40: =(Q40*P40/(P40-1)*(U40-V40)*(K40)/I40)/N40 -> 0.35117367 | X40: =(Q40*P40/(P40-1)*(P40*V40-U40)*(K40)/I40)/N40 -> 0.33348158 | Y40: 20180126 | Z40: 8-69 | AB40: 3 | AD40: Emily | AE40: Turner Designs Aquafluor Handheld Serial Number 800446 | AF40: 1 | AG40: 0
...

Sheet missing
A4: AR24B | B4: 20171027 | C4: L1 | D4: 1 | E4: 4 | H4: a | I4: 282 | J4: 0
A5: AR24B | B5: 20171027 | C5: L1 | D5: 1 | E5: 4 | H5: b | I5: 282 | J5: 0
A6: AR24B | B6: 20171027 | C6: L1 | D6: 1 | E6: 5 | H6: a | I6: 282 | J6: 0
A7: AR24B | B7: 20171027 | C7: L1 | D7: 1 | E7: 5 | H7: b | I7: 282 | J7: 0

Sheet cruise_proj_type
A1: Number | B1: Project
A2: 1 | B2: LTER
A3: 2 | B3: OOI
A4: 3 | B4: JPstudentcruise
A5: 4 | B5: LTER_OOI
A6: 5 | B6: LTER_JPstudentcruise

Sheet Cal_052925
A1: Calibration Date | B1: Cruise_Site | C1: Fluorometer | D1: Personell | E1: CALIBRATION | G1: Blank_Acetone | H1: AvgBlank | I1: Dilution | J1: ug_l | K1: Flurometer_Before_Acid | L1: Fluorometer_After_Acid | M1: Fluorometer_Before_Acid-AvgBlank | N1: Fluorometer_After_Acid-AvgBlank | O1: Acid_Ratio__Before-AvgBlank/After-AvgBlank | P1: Fd__Chl/Before-AvgBlank | Q1: tau | R1: Fd
A2: 45805 | B2: mvco | C2: Turner Designs Aquafluor Handheld Serial Number 800446 | D2: taylor | E2: Cal_052825 | G2: 0.552 | H2: =AVERAGE(G2:G8) -> 0.535 | I2: full(on spec) | J2: =(0.95778-0.000645)/87.67*10^6 -> 10917.475
A3: 20250529 | G3: 0.51 | I3: 20 | J3: =J2/I3 -> 545.87373 | K3: 952 | L3: 523.1 | M3: =K3-H2 -> 951.465 | N3: =L3-H2 -> 522.565 | O3: =M3/N3 -> 1.8207591 | P3: =J3/M3 -> 0.57371919 | Q3: =LINEST(M3:M13,N3:N13,FALSE) -> 1.8033877 | R3: =LINEST(J3:J13,M3:M13,FALSE) -> 0.57372782 | U3: =$Q$3 -> 1.8033877 | V3: 1.9
G4: 0.356 | I4: =I3*2 -> 40 | J4: =J2/I4 -> 272.93687 | K4: 471.5 | L4: 271 | M4: =K4-H2 -> 470.965 | N4: =L4-H2 -> 270.465 | O4: =M4/N4 -> 1.7413159 | P4: =J4/M4 -> 0.57952686 | U4: =$Q$3 -> 1.8033877 | V4: 1.9
G5: 0.72 | I5: =I4*2 -> 80 | J5: =J2/I5 -> 136.46843 | K5: 245.7 | L5: 136.9 | M5: =K5-H2 -> 245.165 | N5: =L5-H2 -> 136.365 | O5: =M5/N5 -> 1.7978587 | P5: =J5/M5 -> 0.55663913 | Q5: old averages | U5: =$Q$3 -> 1.8033877 | V5: 1.9
G6: 0.555 | I6: =I5*2 -> 160 | J6: =J2/I6 -> 68.234216 | K6: 122.2 | L6: 68.85 | M6: =K6-H2 -> 121.665 | N6: =L6-H2 -> 68.315 | O6: =M6/N6 -> 1.7809412 | P6: =J6/M6 -> 0.56083686 | Q6: =AVERAGE(O3:O13) -> 1.7607628 | R6: =AVERAGE(P3:P13) -> 0.56364819 | U6: =$Q$3 -> 1.8033877 | V6: 1.9
G7: 0.517 | I7: =I6*2 -> 320 | J7: =J2/I7 -> 34.117108 | K7: 61.41 | L7: 34.15 | M7: =K7-H2 -> 60.875 | N7: =L7-H2 -> 33.615 | O7: =M7/N7 -> 1.8109475 | P7: =J7/M7 -> 0.56044531 | U7: =$Q$3 -> 1.8033877 | V7: 1.9
I8: =I7*2 -> 640 | J8: =J2/I8 -> 17.058554 | K8: 30.95 | L8: 17.32 | M8: =K8-H2 -> 30.415 | N8: =L8-H2 -> 16.785 | O8: =M8/N8 -> 1.8120346 | P8: =J8/M8 -> 0.56085991 | U8: =$Q$3 -> 1.8033877 | V8: 1.9
I9: =I8*2 -> 1280 | J9: =J2/I9 -> 8.529277 | K9: 15.31 | L9: 9.134 | M9: =K9-H2 -> 14.775 | N9: =L9-H2 -> 8.599 | O9: =M9/N9 -> 1.718223 | P9: =J9/M9 -> 0.57727763 | U9: =$Q$3 -> 1.8033877 | V9: 1.9
I10: =I9*2 -> 2560 | J10: =J2/I10 -> 4.2646385 | K10: 7.925 | L10: 4.568 | M10: =K10-H2 -> 7.39 | N10: =L10-H2 -> 4.033 | O10: =M10/N10 -> 1.8323828 | P10: =J10/M10 -> 0.57708234 | U10: =$Q$3 -> 1.8033877 | V10: 1.9
I11: =I10*2 -> 5120 | J11: =J2/I11 -> 2.1323193 | K11: 4.405 | L11: 2.767 | M11: =K11-H2 -> 3.87 | N11: =L11-H2 -> 2.232 | O11: =M11/N11 -> 1.733871 | P11: =J11/M11 -> 0.55098689 | U11: =$Q$3 -> 1.8033877 | V11: 1.9
I12: =I11*2 -> 10240 | J12: =J2/I12 -> 1.0661596 | K12: 2.337 | L12: 1.662 | M12: =K12-H2 -> 1.802 | N12: =L12-H2 -> 1.127 | O12: =M12/N12 -> 1.5989352 | P12: =J12/M12 -> 0.59165351 | U12: =$Q$3 -> 1.8033877 | V12: 1.9
I13: 20480 | J13: =J2/I13 -> 0.53307982 | K13: 1.578 | L13: 1.141 | M13: =K13-H2 -> 1.043 | N13: =L13-H2 -> 0.606 | O13: =M13/N13 -> 1.7211221 | P13: =J13/M13 -> 0.51110241 | U13: =$Q$3 -> 1.8033877 | V13: 1.9
I17: =(0.04923-0.000378)/87.67*10^6 -> 557.22596 | J17: spinach_5percent | R17: *** The 1/20 dilution was done using a 5ml volumetric flask of chl-a stock into 100ml volumetric diluted with 90% acetone
I18: =I17/J2 -> 0.051039822
I19: =J2/I17 -> 19.592545
I22: =(0.049657-0.000606)/87.67*10^6 -> 559.49584 | J22: spinach_5percent
I23: =I22/J2 -> 0.051247734
I24: =J2/I22 -> 19.513058

Sheet Cal_030724
A1: Calibration Date | B1: Cruise_Site | C1: Fluorometer | D1: Personell | E1: CALIBRATION | G1: Blank_Acetone | H1: AvgBlank | I1: Dilution | J1: ug_l | K1: Flurometer_Before_Acid | L1: Fluorometer_After_Acid | M1: Fluorometer_Before_Acid-AvgBlank | N1: Fluorometer_After_Acid-AvgBlank | O1: Acid_Ratio__Before-AvgBlank/After-AvgBlank | P1: Fd__Chl/Before-AvgBlank | Q1: tau | R1: Fd
A2: 45358 | B2: mvco | C2: Turner Designs Aquafluor Handheld Serial Number 800446 | D2: taylor | E2: Cal_030724 | G2: 0.645 | H2: =AVERAGE(G2:G8) -> 0.67066667 | I2: full(on spec) | J2: =(1.046733-0.001627)/87.67*10^6 -> 11920.908
A3: 20240307 | G3: 0.708 | I3: 20 | J3: =J2/I3 -> 596.0454 | K3: 1021 | L3: 560.5 | M3: =K3-H2 -> 1020.3293 | N3: =L3-H2 -> 559.82933 | O3: =M3/N3 -> 1.8225721 | P3: =J3/M3 -> 0.58416962 | Q3: =LINEST(M3:M13,N3:N13,FALSE) -> 1.8135132 | R3: =LINEST(J3:J13,M3:M13,FALSE) -> 0.57626673 | U3: =$Q$3 -> 1.8135132 | V3: 1.9
G4: 0.546 | I4: =I3*2 -> 40 | J4: =J2/I4 -> 298.0227 | K4: 535.8 | L4: 299.8 | M4: =K4-H2 -> 535.12933 | N4: =L4-H2 -> 299.12933 | O4: =M4/N4 -> 1.7889564 | P4: =J4/M4 -> 0.55691714 | U4: =$Q$3 -> 1.8135132 | V4: 1.9
G5: 0.89 | I5: =I4*2 -> 80 | J5: =J2/I5 -> 149.01135 | K5: 271.3 | L5: 151.5 | M5: =K5-H2 -> 270.62933 | N5: =L5-H2 -> 150.82933 | O5: =M5/N5 -> 1.7942752 | P5: =J5/M5 -> 0.55061049 | Q5: old averages | U5: =$Q$3 -> 1.8135132 | V5: 1.9
G6: 0.613 | I6: =I5*2 -> 160 | J6: =J2/I6 -> 74.505675 | K6: 137.2 | L6: 77.14 | M6: =K6-H2 -> 136.52933 | N6: =L6-H2 -> 76.469333 | O6: =M6/N6 -> 1.7854129 | P6: =J6/M6 -> 0.54571185 | Q6: =AVERAGE(O3:O13) -> 1.809832 | R6: =AVERAGE(P3:P13) -> 0.54645901 | U6: =$Q$3 -> 1.8135132 | V6: 1.9
G7: 0.622 | I7: =I6*2 -> 320 | J7: =J2/I7 -> 37.252837 | K7: 69.99 | L7: 39.17 | M7: =K7-H2 -> 69.319333 | N7: =L7-H2 -> 38.499333 | O7: =M7/N7 -> 1.8005333 | P7: =J7/M7 -> 0.53740905 | U7: =$Q$3 -> 1.8135132 | V7: 1.9
I8: =I7*2 -> 640 | J8: =J2/I8 -> 18.626419 | K8: 34.94 | L8: 19.98 | M8: =K8-H2 -> 34.269333 | N8: =L8-H2 -> 19.309333 | O8: =M8/N8 -> 1.7747549 | P8: =J8/M8 -> 0.54353023 | U8: =$Q$3 -> 1.8135132 | V8: 1.9
I9: =I8*2 -> 1280 | J9: =J2/I9 -> 9.3132093 | K9: 17.8 | L9: 10.27 | M9: =K9-H2 -> 17.129333 | N9: =L9-H2 -> 9.5993333 | O9: =M9/N9 -> 1.7844295 | P9: =J9/M9 -> 0.54369946 | U9: =$Q$3 -> 1.8135132 | V9: 1.9
I10: =I9*2 -> 2560 | J10: =J2/I10 -> 4.6566047 | K10: 9.253 | L10: 5.76 | M10: =K10-H2 -> 8.5823333 | N10: =L10-H2 -> 5.0893333 | O10: =M10/N10 -> 1.6863374 | P10: =J10/M10 -> 0.54258026 | U10: =$Q$3 -> 1.8135132 | V10: 1.9
I11: =I10*2 -> 5120 | J11: =J2/I11 -> 2.3283023 | K11: 4.913 | L11: 3.058 | M11: =K11-H2 -> 4.2423333 | N11: =L11-H2 -> 2.3873333 | O11: =M11/N11 -> 1.7770176 | P11: =J11/M11 -> 0.54882588 | U11: =$Q$3 -> 1.8135132 | V11: 1.9
I12: =I11*2 -> 10240 | J12: =J2/I12 -> 1.1641512 | K12: 2.695 | L12: 1.836 | M12: =K12-H2 -> 2.0243333 | N12: =L12-H2 -> 1.1653333 | O12: =M12/N12 -> 1.7371281 | P12: =J12/M12 -> 0.57507879 | U12: =$Q$3 -> 1.8135132 | V12: 1.9
I13: 20480 | J13: =J2/I13 -> 0.58207558 | K13: 1.877 | L13: 1.23 | M13: =K13-H2 -> 1.2063333 | N13: =L13-H2 -> 0.55933333 | O13: =M13/N13 -> 2.1567342 | P13: =J13/M13 -> 0.48251637 | U13: =$Q$3 -> 1.8135132 | V13: 1.9
I17: =(0.054542-0.000256)/87.67*10^6 -> 619.2084 | J17: spinach_5percent | R17: *** The 1/20 dilution was done using a 5ml volumetric flask of chl-a stock into 100ml volumetric diluted with 90% acetone
I18: =I17/J2 -> 0.051943056
I19: =J2/I17 -> 19.251851
I22: =(0.052878-0.00028)/87.67*10^6 -> 599.95437 | J22: spinach_5percent
I23: =I22/J2 -> 0.050327909
I24: =J2/I22 -> 19.869691

Sheet Cal_051922a
A1: Calibration Date | B1: Cruise_Site | C1: Fluorometer | D1: Personell | E1: CALIBRATION | G1: Blank_Acetone | H1: AvgBlank | I1: Dilution | J1: ug_l | K1: Flurometer_Before_Acid | L1: Fluorometer_After_Acid | M1: Fluorometer_Before_Acid-AvgBlank | N1: Fluorometer_After_Acid-AvgBlank | O1: Acid_Ratio__Before-AvgBlank/After-AvgBlank | P1: Fd__Chl/Before-AvgBlank | Q1: tau | R1: Fd
A2: 44700 | C2: Turner Designs Aquafluor Handheld Serial Number 800446 | D2: taylor | E2: Cal_051922a | G2: 0.59 | H2: =AVERAGE(G2:G8) -> 0.54816667 | I2: full(on spec) | J2: =(1.135439-0.001168)/87.67*10^6 -> 12937.961
A3: 20220519 | G3: 0.501 | I3: 20 | J3: =J2/I3 -> 646.89803 | K3: 1145 | L3: 616.3 | M3: =K3-H2 -> 1144.4518 | N3: =L3-H2 -> 615.75183 | O3: =M3/N3 -> 1.8586251 | P3: =J3/M3 -> 0.56524705 | Q3: =LINEST(M3:M13,N3:N13,FALSE) -> 1.8382409 | R3: =LINEST(J3:J13,M3:M13,FALSE) -> 0.56187209 | U3: =$Q$3 -> 1.8382409 | V3: 1.9
G4: 0.602 | I4: =I3*2 -> 40 | J4: =J2/I4 -> 323.44901 | K4: 583 | L4: 327 | M4: =K4-H2 -> 582.45183 | N4: =L4-H2 -> 326.45183 | O4: =M4/N4 -> 1.7841892 | P4: =J4/M4 -> 0.5553232 | U4: =$Q$3 -> 1.8382409 | V4: 1.9
G5: 0.356 | I5: =I4*2 -> 80 | J5: =J2/I5 -> 161.72451 | K5: 298 | L5: 166.8 | M5: =K5-H2 -> 297.45183 | N5: =L5-H2 -> 166.25183 | O5: =M5/N5 -> 1.7891642 | P5: =J5/M5 -> 0.54369981 | Q5: old averages | U5: =$Q$3 -> 1.8382409 | V5: 1.9
G6: 0.598 | I6: =I5*2 -> 160 | J6: =J2/I6 -> 80.862253 | K6: 149 | L6: 85.09 | M6: =K6-H2 -> 148.45183 | N6: =L6-H2 -> 84.541833 | O6: =M6/N6 -> 1.7559571 | P6: =J6/M6 -> 0.54470364 | Q6: =AVERAGE(O3:O13) -> 1.8248962 | R6: =AVERAGE(P3:P13) -> 0.55956624 | U6: =$Q$3 -> 1.8382409 | V6: 1.9
G7: 0.642 | I7: =I6*2 -> 320 | J7: =J2/I7 -> 40.431127 | K7: 76.53 | L7: 42.11 | M7: =K7-H2 -> 75.981833 | N7: =L7-H2 -> 41.561833 | O7: =M7/N7 -> 1.8281637 | P7: =J7/M7 -> 0.5321157 | U7: =$Q$3 -> 1.8382409 | V7: 1.9
I8: =I7*2 -> 640 | J8: =J2/I8 -> 20.215563 | K8: 38.1 | L8: 21.23 | M8: =K8-H2 -> 37.551833 | N8: =L8-H2 -> 20.681833 | O8: =M8/N8 -> 1.8156917 | P8: =J8/M8 -> 0.53833759 | U8: =$Q$3 -> 1.8382409 | V8: 1.9
I9: =I8*2 -> 1280 | J9: =J2/I9 -> 10.107782 | K9: 19.2 | L9: 10.49 | M9: =K9-H2 -> 18.651833 | N9: =L9-H2 -> 9.9418333 | O9: =M9/N9 -> 1.876096 | P9: =J9/M9 -> 0.54191894 | U9: =$Q$3 -> 1.8382409 | V9: 1.9
I10: =I9*2 -> 2560 | J10: =J2/I10 -> 5.0538908 | K10: 9.529 | L10: 5.53 | M10: =K10-H2 -> 8.9808333 | N10: =L10-H2 -> 4.9818333 | O10: =M10/N10 -> 1.8027165 | P10: =J10/M10 -> 0.56274186 | U10: =$Q$3 -> 1.8382409 | V10: 1.9
I11: =I10*2 -> 5120 | J11: =J2/I11 -> 2.5269454 | K11: 5.299 | L11: 3.104 | M11: =K11-H2 -> 4.7508333 | N11: =L11-H2 -> 2.5558333 | O11: =M11/N11 -> 1.8588197 | P11: =J11/M11 -> 0.53189519 | U11: =$Q$3 -> 1.8382409 | V11: 1.9
I12: =I11*2 -> 10240 | J12: =J2/I12 -> 1.2634727 | K12: 2.88 | L12: 1.572 | M12: =K12-H2 -> 2.3318333 | N12: =L12-H2 -> 1.0238333 | O12: =M12/N12 -> 2.2775517 | P12: =J12/M12 -> 0.54183663 | U12: =$Q$3 -> 1.8382409 | V12: 1.9
I13: 20480 | J13: =J2/I13 -> 0.63173635 | K13: 1.454 | L13: 1.183 | M13: =K13-H2 -> 0.90583333 | N13: =L13-H2 -> 0.63483333 | O13: =M13/N13 -> 1.4268837 | P13: =J13/M13 -> 0.69740904 | U13: =$Q$3 -> 1.8382409 | V13: 1.9
I17: =(0.057354-0.000234)/87.67*10^6 -> 651.53416 | J17: spinach_5percent | R17: *** The 1/20 dilution was done using a 5ml volumetric flask of chl-a stock into 100ml volumetric diluted with 90% acetone
I18: =I17/J2 -> 0.050358336
I19: =J2/I17 -> 19.857686

Sheet Cal_111320b_12mm
A1: Calibration Date | B1: Cruise_Site | C1: Fluorometer | D1: Personell | E1: CALIBRATION | G1: Blank_Acetone | H1: AvgBlank | I1: Dilution | J1: ug_l | K1: Flurometer_Before_Acid | L1: Fluorometer_After_Acid | M1: Fluorometer_Before_Acid-AvgBlank | N1: Fluorometer_After_Acid-AvgBlank | O1: Acid_Ratio__Before-AvgBlank/After-AvgBlank | P1: Fd__Chl/Before-AvgBlank | Q1: tau | R1: Fd
A2: 44148 | B2: mvco | C2: Turner Designs Aquafluor Handheld 800446 | D2: taylor | E2: Cal_111320b_12mm | G2: 0.659 | H2: =AVERAGE(G2:G7) -> 0.507 | I2: full(on spec) | J2: =(0.961182-0.001831)/87.67*10^6 -> 10942.751
A3: 20201113 | G3: 0.468 | I3: 20 | J3: =J2/I3 -> 547.13756 | K3: 991.7 | L3: 539.2 | M3: =K3-H2 -> 991.193 | N3: =L3-H2 -> 538.693 | O3: =M3/N3 -> 1.8399961 | P3: =J3/M3 -> 0.55199902 | Q3: =LINEST(M3:M13,N3:N13,FALSE) -> 1.8343281 | R3: =LINEST(J3:J13,M3:M13,FALSE) -> 0.54419534 | U3: =$Q$3 -> 1.8343281 | V3: 1.9
G4: 0.543 | I4: =I3*2 -> 40 | J4: =J2/I4 -> 273.56878 | K4: 520.9 | L4: 286.4 | M4: =K4-H2 -> 520.393 | N4: =L4-H2 -> 285.893 | O4: =M4/N4 -> 1.8202369 | P4: =J4/M4 -> 0.5256965 | U4: =$Q$3 -> 1.8343281 | V4: 1.9
G5: 0.276 | I5: =I4*2 -> 80 | J5: =J2/I5 -> 136.78439 | K5: 264.2 | L5: 145.4 | M5: =K5-H2 -> 263.693 | N5: =L5-H2 -> 144.893 | O5: =M5/N5 -> 1.8199154 | P5: =J5/M5 -> 0.51872591 | Q5: old averages | U5: =$Q$3 -> 1.8343281 | V5: 1.9
G6: 0.498 | I6: =I5*2 -> 160 | J6: =J2/I6 -> 68.392195 | K6: 135.4 | L6: 75.03 | M6: =K6-H2 -> 134.893 | N6: =L6-H2 -> 74.523 | O6: =M6/N6 -> 1.8100855 | P6: =J6/M6 -> 0.50701071 | Q6: =AVERAGE(O3:O13) -> 1.7190352 | R6: =AVERAGE(P3:P13) -> 0.55186569 | U6: =$Q$3 -> 1.8343281 | V6: 1.9
G7: 0.598 | I7: =I6*2 -> 320 | J7: =J2/I7 -> 34.196098 | K7: 68.3 | L7: 37.96 | M7: =K7-H2 -> 67.793 | N7: =L7-H2 -> 37.453 | O7: =M7/N7 -> 1.810082 | P7: =J7/M7 -> 0.5044193 | U7: =$Q$3 -> 1.8343281 | V7: 1.9
I8: =I7*2 -> 640 | J8: =J2/I8 -> 17.098049 | K8: 33.08 | L8: 18.72 | M8: =K8-H2 -> 32.573 | N8: =L8-H2 -> 18.213 | O8: =M8/N8 -> 1.7884478 | P8: =J8/M8 -> 0.52491477 | U8: =$Q$3 -> 1.8343281 | V8: 1.9
I9: =I8*2 -> 1280 | J9: =J2/I9 -> 8.5490244 | K9: 16.95 | L9: 9.641 | M9: =K9-H2 -> 16.443 | N9: =L9-H2 -> 9.134 | O9: =M9/N9 -> 1.8001971 | P9: =J9/M9 -> 0.51991877 | U9: =$Q$3 -> 1.8343281 | V9: 1.9
I10: =I9*2 -> 2560 | J10: =J2/I10 -> 4.2745122 | K10: 8.432 | L10: 5.149 | M10: =K10-H2 -> 7.925 | N10: =L10-H2 -> 4.642 | O10: =M10/N10 -> 1.7072383 | P10: =J10/M10 -> 0.53937062 | U10: =$Q$3 -> 1.8343281 | V10: 1.9
I11: =I10*2 -> 5120 | J11: =J2/I11 -> 2.1372561 | K11: 4.268 | L11: 2.642 | M11: =K11-H2 -> 3.761 | N11: =L11-H2 -> 2.135 | O11: =M11/N11 -> 1.7615925 | P11: =J11/M11 -> 0.56826804 | U11: =$Q$3 -> 1.8343281 | V11: 1.9
I12: =I11*2 -> 10240 | J12: =J2/I12 -> 1.068628 | K12: 2.355 | L12: 1.724 | M12: =K12-H2 -> 1.848 | N12: =L12-H2 -> 1.217 | O12: =M12/N12 -> 1.5184881 | P12: =J12/M12 -> 0.57826193 | U12: =$Q$3 -> 1.8343281 | V12: 1.9
I13: 20480 | J13: =J2/I13 -> 0.53431402 | K13: 1.237 | L13: 1.099 | M13: =K13-H2 -> 0.73 | N13: =L13-H2 -> 0.592 | O13: =M13/N13 -> 1.2331081 | P13: =J13/M13 -> 0.73193702 | U13: =$Q$3 -> 1.8343281 | V13: 1.9
H17: 44148 | I17: =(0.048584-0)/87.67*10^6 -> 554.16904 | J17: spinach_5percent | R17: *** The 1/20 dilution was done using a 5ml volumetric flask of chl-a stock into 100ml volumetric diluted with 90% acetone
I18: =I17/J2 -> 0.05064257
I19: =J2/I17 -> 19.746233
H21: 43126 | J21: spinach_5percent2
I22: =I21/J2 -> 0
I23: =J2/I21 -> #DIV/0!

Sheet Cal_111320
A1: Calibration Date | B1: Cruise_Site | C1: Fluorometer | D1: Personell | E1: CALIBRATION | G1: Blank_Acetone | H1: AvgBlank | I1: Dilution | J1: ug_l | K1: Flurometer_Before_Acid | L1: Fluorometer_After_Acid | M1: Fluorometer_Before_Acid-AvgBlank | N1: Fluorometer_After_Acid-AvgBlank | O1: Acid_Ratio__Before-AvgBlank/After-AvgBlank | P1: Fd__Chl/Before-AvgBlank | Q1: tau | R1: Fd
A2: 44148 | B2: mvco | C2: Turner Designs Aquafluor Handheld 800446 | D2: taylor | E2: Cal_111320_12mm | G2: 0.58 | H2: =AVERAGE(G2:G8) -> 0.59871429 | I2: full(on spec) | J2: =(0.897217-0.001343)/87.67*10^6 -> 10218.707
G3: 0.612 | I3: 20 | J3: =J2/I3 -> 510.93533 | K3: 935.8 | L3: 494.5 | M3: =K3-H2 -> 935.20129 | N3: =L3-H2 -> 493.90129 | O3: =M3/N3 -> 1.8934984 | P3: =J3/M3 -> 0.54633728 | Q3: =LINEST(M3:M13,N3:N13,FALSE) -> 1.8663069 | R3: =LINEST(J3:J13,M3:M13,FALSE) -> 0.5388603 | U3: =$Q$3 -> 1.8663069 | V3: 1.9
G4: 0.584 | I4: =I3*2 -> 40 | J4: =J2/I4 -> 255.46766 | K4: 490.6 | L4: 272.2 | M4: =K4-H2 -> 490.00129 | N4: =L4-H2 -> 271.60129 | O4: =M4/N4 -> 1.8041199 | P4: =J4/M4 -> 0.52136121 | U4: =$Q$3 -> 1.8663069 | V4: 1.9
G5: 0.562 | I5: =I4*2 -> 80 | J5: =J2/I5 -> 127.73383 | K5: 249.8 | L5: 140.6 | M5: =K5-H2 -> 249.20129 | N5: =L5-H2 -> 140.00129 | O5: =M5/N5 -> 1.7799928 | P5: =J5/M5 -> 0.51257292 | Q5: old averages | U5: =$Q$3 -> 1.8663069 | V5: 1.9
G6: 0.359 | I6: =I5*2 -> 160 | J6: =J2/I6 -> 63.866916 | K6: 126.6 | L6: 70.54 | M6: =K6-H2 -> 126.00129 | N6: =L6-H2 -> 69.941286 | O6: =M6/N6 -> 1.8015294 | P6: =J6/M6 -> 0.50687511 | Q6: =AVERAGE(O3:O13) -> 1.8207116 | R6: =AVERAGE(P3:P13) -> 0.53586737 | U6: =$Q$3 -> 1.8663069 | V6: 1.9
G7: 0.775 | I7: =I6*2 -> 320 | J7: =J2/I7 -> 31.933458 | K7: 64.16 | L7: 35.03 | M7: =K7-H2 -> 63.561286 | N7: =L7-H2 -> 34.431286 | O7: =M7/N7 -> 1.8460329 | P7: =J7/M7 -> 0.50240421 | U7: =$Q$3 -> 1.8663069 | V7: 1.9
G8: 0.719 | I8: =I7*2 -> 640 | J8: =J2/I8 -> 15.966729 | K8: 32.45 | L8: 18.05 | M8: =K8-H2 -> 31.851286 | N8: =L8-H2 -> 17.451286 | O8: =M8/N8 -> 1.8251541 | P8: =J8/M8 -> 0.50128993 | U8: =$Q$3 -> 1.8663069 | V8: 1.9
I9: =I8*2 -> 1280 | J9: =J2/I9 -> 7.9833645 | K9: 16.52 | L9: 9.203 | M9: =K9-H2 -> 15.921286 | N9: =L9-H2 -> 8.6042857 | O9: =M9/N9 -> 1.8503902 | P9: =J9/M9 -> 0.50142712 | U9: =$Q$3 -> 1.8663069 | V9: 1.9
I10: =I9*2 -> 2560 | J10: =J2/I10 -> 3.9916822 | K10: 8.466 | L10: 4.757 | M10: =K10-H2 -> 7.8672857 | N10: =L10-H2 -> 4.1582857 | O10: =M10/N10 -> 1.8919541 | P10: =J10/M10 -> 0.50737731 | U10: =$Q$3 -> 1.8663069 | V10: 1.9
I11: =I10*2 -> 5120 | J11: =J2/I11 -> 1.9958411 | K11: 4.617 | L11: 2.565 | M11: =K11-H2 -> 4.0182857 | N11: =L11-H2 -> 1.9662857 | O11: =M11/N11 -> 2.043592 | P11: =J11/M11 -> 0.4966897 | U11: =$Q$3 -> 1.8663069 | V11: 1.9
I12: =I11*2 -> 10240 | J12: =J2/I12 -> 0.99792056 | K12: 2.559 | L12: 1.812 | M12: =K12-H2 -> 1.9602857 | N12: =L12-H2 -> 1.2132857 | O12: =M12/N12 -> 1.6156835 | P12: =J12/M12 -> 0.50906893 | U12: =$Q$3 -> 1.8663069 | V12: 1.9
I13: 20480 | J13: =J2/I13 -> 0.49896028 | K13: 1.231 | L13: 0.976 | M13: =K13-H2 -> 0.63228571 | N13: =L13-H2 -> 0.37728571 | O13: =M13/N13 -> 1.6758803 | P13: =J13/M13 -> 0.78913736 | U13: =$Q$3 -> 1.8663069 | V13: 1.9
H17: 44148 | I17: =(0.045654-0.001099)/87.67*10^6 -> 508.21262 | J17: spinach_5percent | R17: *** The 1/20 dilution was done using a 5ml volumetric flask of chl-a stock into 100ml volumetric diluted with 90% acetone
I18: =I17/J2 -> 0.049733556
I19: =J2/I17 -> 20.107148
H21: 43126 | J21: spinach_5percent2
I22: =I21/J2 -> 0
I23: =J2/I21 -> #DIV/0!

Sheet Cal_110119
B2: Calibration name = Cal_110119 | O2: Cal_date | P2: Calibration name | Q2: tau | R2: Fd
O3: 20181101 | P3: Cal_110119 | Q3: 1.8682 | R3: 0.5122
B5: For Tau, average 2018 and 2020 used cablibration taus
B6: 2019 Tau = 1.8682
B10: Plot average solid standard of each calibration day vs Fd of that calibration. Linear line fit to all calibrations that were used for this Aquafluor
B11: Take the grouping of 2019 data that needs this calibration and average the solid standard for all of the days samples were analyzed
B12: Caliculate the Fd from putting the averaged standard value into the line fit.
B14: 2019 average solid standard = 27.6778
B15: line fit is y = -106.0398*x + 81.9895
B16: 2019 Fd = 0.5122
B19: Apply this cal to LabNB 9-37 to 9-100 and 10-01 to 10-45
B20: This cal will apply to samples run between 11/1/2018 and 12/22/2019

Sheet Cal_012618_12mm
A1: Calibration Date | B1: Cruise_Site | C1: Fluorometer | D1: Personell | E1: CALIBRATION | G1: Blank_Acetone | H1: AvgBlank | I1: Dilution | J1: ug_l | K1: Flurometer_Before_Acid | L1: Fluorometer_After_Acid | M1: Fluorometer_Before_Acid-AvgBlank | N1: Fluorometer_After_Acid-AvgBlank | O1: Acid_Ratio__Before-AvgBlank/After-AvgBlank | P1: Fd__Chl/Before-AvgBlank | Q1: tau | R1: Fd
A2: 43126 | B2: mvco | C2: Turner Designs Aquafluor Handheld 800446 | D2: taylor | E2: Cal_012618_12mm | G2: 0.635 | H2: =AVERAGE(G2:G7) -> 0.67883333 | I2: full(on spec) | J2: =(1.004639-0.001709)/87.67*10^6 -> 11439.831
G3: 0.891 | I3: 20 | J3: =J2/I3 -> 571.99156 | K3: 1166 | L3: 609.5 | M3: =K3-H2 -> 1165.3212 | N3: =L3-H2 -> 608.82117 | O3: =M3/N3 -> 1.9140615 | P3: =J3/M3 -> 0.49084456 | Q3: =LINEST(M3:M13,N3:N13,FALSE) -> 1.9020156 | R3: =LINEST(J3:J13,M3:M13,FALSE) -> 0.48423689 | U3: =$Q$3 -> 1.9020156 | V3: 1.9
G4: 0.532 | I4: =I3*2 -> 40 | J4: =J2/I4 -> 285.99578 | K4: 610.3 | L4: 326.5 | M4: =K4-H2 -> 609.62117 | N4: =L4-H2 -> 325.82117 | O4: =M4/N4 -> 1.87103 | P4: =J4/M4 -> 0.46913689 | U4: =$Q$3 -> 1.9020156 | V4: 1.9
G5: 0.768 | I5: =I4*2 -> 80 | J5: =J2/I5 -> 142.99789 | K5: 312 | L5: 167.3 | M5: =K5-H2 -> 311.32117 | N5: =L5-H2 -> 166.62117 | O5: =M5/N5 -> 1.8684371 | P5: =J5/M5 -> 0.45932595 | Q5: old averages | U5: =$Q$3 -> 1.9020156 | V5: 1.9
G6: 0.561 | I6: =I5*2 -> 160 | J6: =J2/I6 -> 71.498945 | K6: 157.4 | L6: 84.59 | M6: =K6-H2 -> 156.72117 | N6: =L6-H2 -> 83.911167 | O6: =M6/N6 -> 1.8677033 | P6: =J6/M6 -> 0.45621754 | Q6: =AVERAGE(O3:O13) -> 1.8812046 | R6: =AVERAGE(P3:P13) -> 0.4561903 | U6: =$Q$3 -> 1.9020156 | V6: 1.9
G7: 0.686 | I7: =I6*2 -> 320 | J7: =J2/I7 -> 35.749472 | K7: 79.69 | L7: 41.8 | M7: =K7-H2 -> 79.011167 | N7: =L7-H2 -> 41.121167 | O7: =M7/N7 -> 1.9214233 | P7: =J7/M7 -> 0.45246101 | U7: =$Q$3 -> 1.9020156 | V7: 1.9
I8: =I7*2 -> 640 | J8: =J2/I8 -> 17.874736 | K8: 39.86 | L8: 22.04 | M8: =K8-H2 -> 39.181167 | N8: =L8-H2 -> 21.361167 | O8: =M8/N8 -> 1.8342241 | P8: =J8/M8 -> 0.45620735 | U8: =$Q$3 -> 1.9020156 | V8: 1.9
I9: =I8*2 -> 1280 | J9: =J2/I9 -> 8.9373681 | K9: 20.43 | L9: 11.28 | M9: =K9-H2 -> 19.751167 | N9: =L9-H2 -> 10.601167 | O9: =M9/N9 -> 1.8631126 | P9: =J9/M9 -> 0.45249824 | U9: =$Q$3 -> 1.9020156 | V9: 1.9
I10: =I9*2 -> 2560 | J10: =J2/I10 -> 4.4686841 | K10: 10.53 | L10: 5.816 | M10: =K10-H2 -> 9.8511667 | N10: =L10-H2 -> 5.1371667 | O10: =M10/N10 -> 1.9176264 | P10: =J10/M10 -> 0.45361978 | U10: =$Q$3 -> 1.9020156 | V10: 1.9
I11: =I10*2 -> 5120 | J11: =J2/I11 -> 2.234342 | K11: 5.945 | L11: 3.38 | M11: =K11-H2 -> 5.2661667 | N11: =L11-H2 -> 2.7011667 | O11: =M11/N11 -> 1.9495897 | P11: =J11/M11 -> 0.42428244 | U11: =$Q$3 -> 1.9020156 | V11: 1.9
I12: =I11*2 -> 10240 | J12: =J2/I12 -> 1.117171 | K12: 3.209 | L12: 1.994 | M12: =K12-H2 -> 2.5301667 | N12: =L12-H2 -> 1.3151667 | O12: =M12/N12 -> 1.9238373 | P12: =J12/M12 -> 0.44154048 | U12: =$Q$3 -> 1.9020156 | V12: 1.9
I13: 20480 | J13: =J2/I13 -> 0.55858551 | K13: 1.888 | L13: 1.365 | M13: =K13-H2 -> 1.2091667 | N13: =L13-H2 -> 0.68616667 | O13: =M13/N13 -> 1.7622055 | P13: =J13/M13 -> 0.46195907 | U13: =$Q$3 -> 1.9020156 | V13: 1.9
H17: 43126 | I17: =(0.051514-0.000122)/87.67*10^6 -> 586.19824 | J17: spinach_5percent | R17: *** The 1/20 dilution was done using a 5ml volumetric flask of chl-a stock into 100ml volumetric diluted with 90% acetone
I18: =I17/J2 -> 0.051241861
I19: =J2/I17 -> 19.515294
H21: 43126 | I21: =(0.052368-0.000122)/87.67*10^6 -> 595.93932 | J21: spinach_5percent2
I22: =I21/J2 -> 0.052093366
I23: =J2/I21 -> 19.196302
